Workbook

Sheet Read me
A2: IBCS® notation on The Progressive Corporation's reported figures
A4: One sheet per template. Each sheet has two zones: the source data on the left, the charts to its right. They never overlap.
A6: The workbook is live. On any template sheet the two shaded columns are typed inputs - the reference scenario and the measure. Everything from the variance columns rightwards is a formula, so retyping a figure recalculates the variances and redraws the chart, including changing a bar's colour if the variance changes sign.
A8: The columns to the right of the variances feed the charts. They are derived, not data: Excel colours a whole series rather than a point, so a variance that must be green when positive and red when negative is plotted as two mutually exclusive series.
A10: The words are live too. The shaded cells at the top of each sheet hold the entity, measure, unit, period, reference scenario and message; the greyed lines under them - the subject line and each tier caption - are built from those cells, and the text on the charts is linked to them. Retype the unit once and every caption follows. Nothing a chart says is typed into the chart itself.
A12: Charts follow IBCS® notation: fill encodes how a number came to exist (solid dark actual, solid light prior year, outlined plan, hatched forecast), and variance colour encodes impact rather than sign.
A14: IBCS® does not prescribe colour codes (rule UN 4.1). The palette here is a house choice sampled to match the published reference renders.
A16: A third shade. Cells shaded blue are typed like the others, but hold figures the entity never published - a plan or forecast constructed here on a basis stated under the data and on the Sources sheet. Everything else shaded is as reported. Replace either and the charts follow. Scenarios constructed this way: FC, PL.
A18: Figures are from public filings: SEC EDGAR CIK 0000080661, 10-K Exhibit 13 state tables; SEC EDGAR CIK 0000080661, 10-K and monthly 8-K exhibits; SEC EDGAR CIK 0000080661, 10-Q and 10-K reserve roll-forward; SEC EDGAR CIK 0000080661, XBRL companyfacts; SEC EDGAR CIK 0000080661, monthly 8-K exhibits; SEC EDGAR CIK 0000080661, monthly 8-K exhibits and 10-K; SEC EDGAR CIK 0000080661, monthly 8-K exhibits and XBRL. Every figure is either read from a filing or derived from ones that were, and the Sources sheet says which.
A20: Drawn in IBCS® notation from publicly reported figures. IBCS® is a registered trademark of the IBCS Association; this is not an IBCS Institute publication and is not endorsed by, affiliated with, or produced in cooperation with it.
A22: Not affiliated with, endorsed by, or produced in cooperation with The Progressive Corporation. This workbook is an independent presentation of figures that company published; it is not that company's reporting.

Sheet Sources
A1: Where the figures come from
A3: Sheet | B3: Scenario | C3: Basis | D3: Detail
A4: C01A | B4: AC | C4: filed | D4: Segment premium from the year-to-date block of each December monthly release; state premium from the 10-K annual-report exhibit. Both reconcile to the same companywide total.
A5: C02A | B5: AC | C5: filed | D5: Full-year 2025 segment earned premium and the loss and expense ratios, from the year-to-date block of the December monthly release. Losses and expenses are those ratios applied to earned premium; the underwriting result is what remains.
A6: C03A | B6: AC | C6: filed | D6: Monthly net premiums written, Exhibit 99 to the monthly 8-K. Twelve months reconcile to the 10-K annual figure.
A7: C03A | B7: PY | C7: filed | D7: The same series for 2025.
A8: C03A | B8: FC | C8: assumed | D8: Progressive publishes no forecast. Remaining months are prior-year months grown at the year-to-date pace through Jul (+5.7%).
A9: C04A | B9: AC | C9: filed | D9: Monthly net premiums earned and combined ratio from the 2023 monthly 8-K exhibits; the underwriting result is premium times (100 - combined ratio).
A10: C04A | B10: PL | C10: assumed | D10: Progressive publishes no monthly plan. The target it does publish is a 96 combined ratio - a 4% underwriting margin - applied here to each month's earned premium.
A11: C05X | B11: AC | C11: derived | D11: Earned premium times (100 - combined ratio), both from the monthly 8-K exhibit. The same series C07C draws.
A12: C05X | B12: PY | C12: derived | D12: The same calculation over the twelve months of 2025.
A13: C05X | B13: PL | C13: assumed | D13: The 96 combined ratio target applied to the premium each month actually earned. The target is filed; using it as a monthly plan is this workbook's construction, and it is a floor the company aims to beat rather than a forecast.
A14: C05X | B14: FC | C14: assumed | D14: Remaining months are the prior year's at the year-to-date pace, earning the year-to-date margin - the basis C07C states and the same numbers.
... A42: T04A | B42: PL | C42: assumed | D42: The 96 combined ratio target with the expense ratio held where it actually landed, so the whole of the target falls on losses. The target is filed; resolving it into a statement line is this workbook's construction.
A44: filed = the figure appears in a filing. derived = computed from filed figures by the rule stated beside it. assumed = a modelling choice the entity never published; shaded on its own sheet so it cannot be mistaken for something reported.

Sheet C01A
A1: Entity | B1: The Progressive Corporation
A2: Measure | B2: Net premiums written
A3: Unit | B3: $m
A4: Period | B4: 2021..2025
A5: Reference | B5: PL
A6: Message | B6: Direct auto has grown from 18,911 to 39,631 $m since 2021, +110%, and now writes 48% of premium; Texas and Florida together account for 25% of the 2025 book
A7: Subject | B7: =B2&IF(B3="",""," in "&B3) -> Net premiums written in $m
A9: By segment | B9: 2021 AC | C9: 2022 AC | D9: 2023 AC | E9: 2024 AC | F9: 2025 AC
A10: Agency auto | B10: 17258 | C10: 18334 | D10: 22278 | E10: 26967 | F10: 29825
A11: Direct auto | B11: 18911 | C11: 20944 | D11: 26303 | E11: 33432 | F11: 39631
A12: Property | B12: 2216 | C12: 2402 | D12: 2831 | E12: 3071 | F12: 3102
A13: Commercial | B13: 8016 | C13: 9399 | D13: 10138 | E13: 10953 | F13: 10613
A14: Other | B14: 4 | C14: 2 | D14: 0 | E14: 1 | F14: 3
A15: Total | B15: =SUM(B10:B14) -> 46405 | C15: =SUM(C10:C14) -> 51081 | D15: =SUM(D10:D14) -> 61550 | E15: =SUM(E10:E14) -> 74424 | F15: =SUM(F10:F14) -> 83174
A17: By state | B17: 2025 AC
A18: Texas | B18: 10315
A19: Florida | B19: 10261
A20: California | B20: 4777
A21: Georgia | B21: 4084
A22: New York | B22: 3359
A23: All other | B23: 50378
A24: Total | B24: =SUM(B18:B23) -> 83174
A26: span | B26: =MAX(_xlfn.AGGREGATE(4,6,B15:F15,B24:B24),0.000000001) -> 83174
B38: =IF(ISBLANK(B10),NA(),B10/$B$26) -> 0.20749273 | C38: =IF(ISBLANK(C10),NA(),C10/$B$26) -> 0.22042946 | D38: =IF(ISBLANK(D10),NA(),D10/$B$26) -> 0.26784813 | E38: =IF(ISBLANK(E10),NA(),E10/$B$26) -> 0.32422392 | F38: =IF(ISBLANK(F10),NA(),F10/$B$26) -> 0.35858562
B39: =IF(ISBLANK(B11),NA(),B11/$B$26) -> 0.22736673 | C39: =IF(ISBLANK(C11),NA(),C11/$B$26) -> 0.25180946 | D39: =IF(ISBLANK(D11),NA(),D11/$B$26) -> 0.31624065 | E39: =IF(ISBLANK(E11),NA(),E11/$B$26) -> 0.40195253 | F39: =IF(ISBLANK(F11),NA(),F11/$B$26) -> 0.47648304
B40: =IF(ISBLANK(B12),NA(),B12/$B$26) -> 0.026642941 | C40: =IF(ISBLANK(C12),NA(),C12/$B$26) -> 0.028879217 | D40: =IF(ISBLANK(D12),NA(),D12/$B$26) -> 0.034037079 | E40: =IF(ISBLANK(E12),NA(),E12/$B$26) -> 0.036922596 | F40: =IF(ISBLANK(F12),NA(),F12/$B$26) -> 0.037295309
B41: =IF(ISBLANK(B13),NA(),B13/$B$26) -> 0.096376271 | C41: =IF(ISBLANK(C13),NA(),C13/$B$26) -> 0.11300406 | D41: =IF(ISBLANK(D13),NA(),D13/$B$26) -> 0.12188905 | E41: =IF(ISBLANK(E13),NA(),E13/$B$26) -> 0.13168779 | F41: =IF(ISBLANK(F13),NA(),F13/$B$26) -> 0.12759997
B42: =IF(ISBLANK(B14),NA(),B14/$B$26) -> 4.8091952e-05 | C42: =IF(ISBLANK(C14),NA(),C14/$B$26) -> 2.4045976e-05 | D42: =IF(ISBLANK(D14),NA(),D14/$B$26) -> 0 | E42: =IF(ISBLANK(E14),NA(),E14/$B$26) -> 1.2022988e-05 | F42: =IF(ISBLANK(F14),NA(),F14/$B$26) -> 3.6068964e-05
B43: =IF(ISBLANK(B15),NA(),B15/$B$26) -> 0.55792676 | C43: =IF(ISBLANK(C15),NA(),C15/$B$26) -> 0.61414625 | D43: =IF(ISBLANK(D15),NA(),D15/$B$26) -> 0.74001491 | E43: =IF(ISBLANK(E15),NA(),E15/$B$26) -> 0.89479886 | F43: =IF(ISBLANK(F15),NA(),F15/$B$26) -> 1
B46: =IF(ISBLANK(B18),NA(),B18/$B$26) -> 0.12401712
B47: =IF(ISBLANK(B19),NA(),B19/$B$26) -> 0.12336788
B48: =IF(ISBLANK(B20),NA(),B20/$B$26) -> 0.057433813
B49: =IF(ISBLANK(B21),NA(),B21/$B$26) -> 0.049101883
B50: =IF(ISBLANK(B22),NA(),B22/$B$26) -> 0.040385217
B51: =IF(ISBLANK(B23),NA(),B23/$B$26) -> 0.60569409
B52: =IF(ISBLANK(B24),NA(),B24/$B$26) -> 1
B66: =IF(ISBLANK(B10),"",IF(B10/83180*264<(LEN(TEXT(B10,"# ##0")))*5,"",TEXT(B10,"# ##0"))) -> 17 258 | C66: =IF(ISBLANK(C10),"",IF(C10/83180*264<(LEN(TEXT(C10,"# ##0")))*5,"",TEXT(C10,"# ##0"))) -> 18 334 | D66: =IF(ISBLANK(D10),"",IF(D10/83180*264<(LEN(TEXT(D10,"# ##0")))*5,"",TEXT(D10,"# ##0"))) -> 22 278 | E66: =IF(ISBLANK(E10),"",IF(E10/83180*264<(LEN(TEXT(E10,"# ##0")))*5,"",TEXT(E10,"# ##0"))) -> 26 967 | F66: =IF(ISBLANK(F10),"",IF(F10/83180*264<(LEN(TEXT(F10,"# ##0")))*5,"",TEXT(F10,"# ##0"))) -> 29 825
B67: =IF(ISBLANK(B11),"",IF(B11/83180*264<(LEN(TEXT(B11,"# ##0")))*5,"",TEXT(B11,"# ##0"))) -> 18 911 | C67: =IF(ISBLANK(C11),"",IF(C11/83180*264<(LEN(TEXT(C11,"# ##0")))*5,"",TEXT(C11,"# ##0"))) -> 20 944 | D67: =IF(ISBLANK(D11),"",IF(D11/83180*264<(LEN(TEXT(D11,"# ##0")))*5,"",TEXT(D11,"# ##0"))) -> 26 303 | E67: =IF(ISBLANK(E11),"",IF(E11/83180*264<(LEN(TEXT(E11,"# ##0")))*5,"",TEXT(E11,"# ##0"))) -> 33 432 | F67: =IF(ISBLANK(F11),"",IF(F11/83180*264<(LEN(TEXT(F11,"# ##0")))*5,"",TEXT(F11,"# ##0"))) -> 39 631
B68: =IF(ISBLANK(B12),"",IF(B12/83180*264<(LEN(TEXT(B12,"# ##0")))*5,"",TEXT(B12,"# ##0"))) | C68: =IF(ISBLANK(C12),"",IF(C12/83180*264<(LEN(TEXT(C12,"# ##0")))*5,"",TEXT(C12,"# ##0"))) | D68: =IF(ISBLANK(D12),"",IF(D12/83180*264<(LEN(TEXT(D12,"# ##0")))*5,"",TEXT(D12,"# ##0"))) | E68: =IF(ISBLANK(E12),"",IF(E12/83180*264<(LEN(TEXT(E12,"# ##0")))*5,"",TEXT(E12,"# ##0"))) | F68: =IF(ISBLANK(F12),"",IF(F12/83180*264<(LEN(TEXT(F12,"# ##0")))*5,"",TEXT(F12,"# ##0")))
B69: =IF(ISBLANK(B13),"",IF(B13/83180*264<(LEN(TEXT(B13,"# ##0")))*5,"",TEXT(B13,"# ##0"))) -> 8 016 | C69: =IF(ISBLANK(C13),"",IF(C13/83180*264<(LEN(TEXT(C13,"# ##0")))*5,"",TEXT(C13,"# ##0"))) -> 9 399 | D69: =IF(ISBLANK(D13),"",IF(D13/83180*264<(LEN(TEXT(D13,"# ##0")))*5,"",TEXT(D13,"# ##0"))) -> 10 138 | E69: =IF(ISBLANK(E13),"",IF(E13/83180*264<(LEN(TEXT(E13,"# ##0")))*5,"",TEXT(E13,"# ##0"))) -> 10 953 | F69: =IF(ISBLANK(F13),"",IF(F13/83180*264<(LEN(TEXT(F13,"# ##0")))*5,"",TEXT(F13,"# ##0"))) -> 10 613
...

Sheet C02A
A1: Entity | B1: The Progressive Corporation
A2: Measure | B2: Net premiums earned
A3: Unit | B3: $m
A4: Period | B4: 2025
A5: Reference | B5: PL
A6: Message | B6: Of 81,659 $m earned in 2025, 53,866 went to losses and 17,523 to expenses, leaving an underwriting result of 10,270 $m (12.6%); Property keeps the largest share of its premium at 24.9% and Direct auto the smallest at 9.9%
A7: Subject | B7: =B2&IF(B3="",""," in "&B3) -> Net premiums earned in $m
A9: C02A | B9: Agency auto | C9: Direct auto | D9: Property | E9: Personal Lines | F9: Commercial | G9: Companywide
A10: Losses and LAE | B10: 19186 | C10: 26030 | D10: 1424 | E10: =SUM(B10:D10) -> 46640 | F10: 7225 | G10: =SUM(B10:D10)+F10 -> 53865
A11: Expenses | B11: 5906 | C11: 8460 | D11: 916 | E11: =SUM(B11:D11) -> 15282 | F11: 2241 | G11: =SUM(B11:D11)+F11 -> 17523
A12: Underwriting result | B12: 4290 | C12: 3790 | D12: 776 | E12: =SUM(B12:D12) -> 8856 | F12: 1415 | G12: =SUM(B12:D12)+F12 -> 10271
A13: Total | B13: =SUM(B10:B12) -> 29382 | C13: =SUM(C10:C12) -> 38280 | D13: =SUM(D10:D12) -> 3116 | E13: =SUM(E10:E12) -> 70778 | F13: =SUM(F10:F12) -> 10881 | G13: =SUM(G10:G12) -> 81659
A15: span | B15: =MAX(_xlfn.AGGREGATE(4,6,$B$13:$D$13,$F$13:$F$13),0.000000001) -> 38280
B27: =IF(ISBLANK(B10),NA(),B10/$B$15) -> 0.50120167 | C27: =IF(ISBLANK(C10),NA(),C10/$B$15) -> 0.67998955 | D27: =IF(ISBLANK(D10),NA(),D10/$B$15) -> 0.037199582 | E27: =IF(ISBLANK(E10),NA(),E10/$B$15) -> 1.2183908 | F27: =IF(ISBLANK(F10),NA(),F10/$B$15) -> 0.18874086 | G27: =IF(ISBLANK(G10),NA(),G10/$B$15) -> 1.4071317
B28: =IF(ISBLANK(B11),NA(),B11/$B$15) -> 0.15428422 | C28: =IF(ISBLANK(C11),NA(),C11/$B$15) -> 0.22100313 | D28: =IF(ISBLANK(D11),NA(),D11/$B$15) -> 0.023928945 | E28: =IF(ISBLANK(E11),NA(),E11/$B$15) -> 0.3992163 | F28: =IF(ISBLANK(F11),NA(),F11/$B$15) -> 0.05854232 | G28: =IF(ISBLANK(G11),NA(),G11/$B$15) -> 0.45775862
B29: =IF(ISBLANK(B12),NA(),B12/$B$15) -> 0.11206897 | C29: =IF(ISBLANK(C12),NA(),C12/$B$15) -> 0.099007315 | D29: =IF(ISBLANK(D12),NA(),D12/$B$15) -> 0.020271682 | E29: =IF(ISBLANK(E12),NA(),E12/$B$15) -> 0.23134796 | F29: =IF(ISBLANK(F12),NA(),F12/$B$15) -> 0.036964472 | G29: =IF(ISBLANK(G12),NA(),G12/$B$15) -> 0.26831243
B30: =IF(ISBLANK(B13),NA(),B13/$B$15) -> 0.76755486 | C30: =IF(ISBLANK(C13),NA(),C13/$B$15) -> 1 | D30: =IF(ISBLANK(D13),NA(),D13/$B$15) -> 0.081400209 | E30: =IF(ISBLANK(E13),NA(),E13/$B$15) -> 1.8489551 | F30: =IF(ISBLANK(F13),NA(),F13/$B$15) -> 0.28424765 | G30: =IF(ISBLANK(G13),NA(),G13/$B$15) -> 2.1332027
B44: =IF(ISBLANK(B10),"",IF(B10/38300*492.8<(LEN(TEXT(B10,"# ##0")))*5,"",TEXT(B10,"# ##0"))) -> 19 186 | C44: =IF(ISBLANK(C10),"",IF(C10/38300*492.8<(LEN(TEXT(C10,"# ##0")))*5,"",TEXT(C10,"# ##0"))) -> 26 030 | D44: =IF(ISBLANK(D10),"",IF(D10/38300*492.8<(LEN(TEXT(D10,"# ##0")))*5,"",TEXT(D10,"# ##0"))) | E44: =IF(ISBLANK(E10),"",IF(E10/38300*492.8<(LEN(TEXT(E10,"# ##0")))*5,"",TEXT(E10,"# ##0"))) -> 46 640 | F44: =IF(ISBLANK(F10),"",IF(F10/38300*492.8<(LEN(TEXT(F10,"# ##0")))*5,"",TEXT(F10,"# ##0"))) -> 7 225 | G44: =IF(ISBLANK(G10),"",IF(G10/38300*492.8<(LEN(TEXT(G10,"# ##0")))*5,"",TEXT(G10,"# ##0"))) -> 53 865
B45: =IF(ISBLANK(B11),"",IF(B11/38300*492.8<(LEN(TEXT(B11,"# ##0")))*5,"",TEXT(B11,"# ##0"))) -> 5 906 | C45: =IF(ISBLANK(C11),"",IF(C11/38300*492.8<(LEN(TEXT(C11,"# ##0")))*5,"",TEXT(C11,"# ##0"))) -> 8 460 | D45: =IF(ISBLANK(D11),"",IF(D11/38300*492.8<(LEN(TEXT(D11,"# ##0")))*5,"",TEXT(D11,"# ##0"))) | E45: =IF(ISBLANK(E11),"",IF(E11/38300*492.8<(LEN(TEXT(E11,"# ##0")))*5,"",TEXT(E11,"# ##0"))) -> 15 282 | F45: =IF(ISBLANK(F11),"",IF(F11/38300*492.8<(LEN(TEXT(F11,"# ##0")))*5,"",TEXT(F11,"# ##0"))) -> 2 241 | G45: =IF(ISBLANK(G11),"",IF(G11/38300*492.8<(LEN(TEXT(G11,"# ##0")))*5,"",TEXT(G11,"# ##0"))) -> 17 523
B46: =IF(ISBLANK(B12),"",IF(B12/38300*492.8<(LEN(TEXT(B12,"# ##0"))+LEN(TEXT(B13,"# ##0")))*5,"",TEXT(B12,"# ##0"))) -> 4 290 | C46: =IF(ISBLANK(C12),"",IF(C12/38300*492.8<(LEN(TEXT(C12,"# ##0"))+LEN(TEXT(C13,"# ##0")))*5,"",TEXT(C12,"# ##0"))) | D46: =IF(ISBLANK(D12),"",IF(D12/38300*492.8<(LEN(TEXT(D12,"# ##0"))+LEN(TEXT(D13,"# ##0")))*5,"",TEXT(D12,"# ##0"))) | E46: =IF(ISBLANK(E12),"",IF(E12/38300*492.8<(LEN(TEXT(E12,"# ##0"))+LEN(TEXT(E13,"# ##0")))*5,"",TEXT(E12,"# ##0"))) -> 8 856 | F46: =IF(ISBLANK(F12),"",IF(F12/38300*492.8<(LEN(TEXT(F12,"# ##0"))+LEN(TEXT(F13,"# ##0")))*5,"",TEXT(F12,"# ##0"))) | G46: =IF(ISBLANK(G12),"",IF(G12/38300*492.8<(LEN(TEXT(G12,"# ##0"))+LEN(TEXT(G13,"# ##0")))*5,"",TEXT(G12,"# ##0"))) -> 10 271
B47: =IF(ISBLANK(B13),"",IF(B13/38300*492.8<(LEN(TEXT(B13,"# ##0")))*5,"",TEXT(B13,"# ##0"))) -> 29 382 | C47: =IF(ISBLANK(C13),"",IF(C13/38300*492.8<(LEN(TEXT(C13,"# ##0")))*5,"",TEXT(C13,"# ##0"))) -> 38 280 | D47: =IF(ISBLANK(D13),"",IF(D13/38300*492.8<(LEN(TEXT(D13,"# ##0")))*5,"",TEXT(D13,"# ##0"))) -> 3 116 | E47: =IF(ISBLANK(E13),"",IF(E13/38300*492.8<(LEN(TEXT(E13,"# ##0")))*5,"",TEXT(E13,"# ##0"))) -> 70 778 | F47: =IF(ISBLANK(F13),"",IF(F13/38300*492.8<(LEN(TEXT(F13,"# ##0")))*5,"",TEXT(F13,"# ##0"))) -> 10 881 | G47: =IF(ISBLANK(G13),"",IF(G13/38300*492.8<(LEN(TEXT(G13,"# ##0")))*5,"",TEXT(G13,"# ##0"))) -> 81 659

Sheet C03A
A1: Entity | B1: The Progressive Corporation
A2: Measure | B2: Net premiums written
A3: Unit | B3: $m
A4: Period | B4: 2026
A5: Reference | B5: PY
A6: Message | B6: Net premiums written are running +2.5% to +9.6% above prior year through Jul; on that pace the year closes +4,753 $m (+5.7%) above 2025
A7: Subject | B7: =B2&" in "&B3 -> Net premiums written in $m
A9: var_rel caption | B9: ="Δ"&$B$5&"%" -> ΔPY%
A10: var_abs caption | B10: ="Δ"&$B$5&" "&$B$3 -> ΔPY $m
A12: Period | B12: Scenario | C12: PY | D12: Measure | E12: ΔPY | F12: ΔPY% | G12: Measure AC | H12: Measure FC | I12: ΔPY up | J12: ΔPY down | K12: ΔPY% up | L12: ΔPY% down | M12: up length | N12: down length | O12: span unit | P12: span rel | Q12: ref scaled | R12: measure scaled | S12: measure text | T12: var_abs scaled | U12: var_abs text | V12: abs_up scaled | W12: abs_dn scaled | X12: rel_up scaled | Y12: rel_up text | Z12: rel_dn scaled | AA12: rel_dn text | AB12: rel_up_len scaled | AC12: rel_dn_len scaled
A13: Jan | B13: AC | C13: 6481 | D13: 6735 | E13: =D13-C13 -> 254 | F13: =IF(C13<=0,NA(),(D13-C13)/C13*100) -> 3.9191483 | G13: =IF($B13="AC",$D13,NA()) -> 6735 | H13: =IF($B13="AC",NA(),$D13) -> #N/A | I13: =IF($E13>0,$E13,NA()) -> 254 | J13: =IF($E13<0,$E13,NA()) -> #N/A | K13: =IF($F13>0,$F13,NA()) -> 3.9191483 | L13: =IF($F13<0,$F13,NA()) -> #N/A | M13: =IF($F13>0,$F13,0) -> 3.9191483 | N13: =IF($F13<0,-$F13,0) -> 0 | O13: =MAX(_xlfn.AGGREGATE(4,6,C13:C24,D13:D24,E13:E24,I13:I24,J13:J24),-_xlfn.AGGREGATE(5,6,C13:C24,D13:D24,E13:E24,I13:I24,J13:J24),0.000000001) -> 9911 | P13: =MAX(_xlfn.AGGREGATE(4,6,K13:K24,L13:L24,M13:M24,N13:N24),-_xlfn.AGGREGATE(5,6,K13:K24,L13:L24,M13:M24,N13:N24),0.000000001) -> 9.6228293 | Q13: =C13/$O$13 -> 0.65391989 | R13: =D13/$O$13 -> 0.67954798 | S13: =IF(ISNA(D13),"",TEXT(D13,"0")) -> 6735 | T13: =E13/$O$13 -> 0.02562809 | U13: =IF(ISNA(E13),"",TEXT(E13,"+0;-0")) -> +254 | V13: =I13/$O$13 -> 0.02562809 | W13: =J13/$O$13 -> #N/A | X13: =K13/$P$13 -> 0.40727609 | Y13: =IF(ISNA(K13),"",TEXT(K13,"+0.0;-0.0")) -> +3.9 | Z13: =L13/$P$13 -> #N/A | AA13: =IF(ISNA(L13),"",TEXT(L13,"+0.0;-0.0")) | AB13: =M13/$P$13 -> 0.40727609 | AC13: =N13/$P$13 -> 0
A14: Feb | B14: AC | C14: 6684 | D14: 6995 | E14: =D14-C14 -> 311 | F14: =IF(C14<=0,NA(),(D14-C14)/C14*100) -> 4.6529025 | G14: =IF($B14="AC",$D14,NA()) -> 6995 | H14: =IF($B14="AC",NA(),$D14) -> #N/A | I14: =IF($E14>0,$E14,NA()) -> 311 | J14: =IF($E14<0,$E14,NA()) -> #N/A | K14: =IF($F14>0,$F14,NA()) -> 4.6529025 | L14: =IF($F14<0,$F14,NA()) -> #N/A | M14: =IF($F14>0,$F14,0) -> 4.6529025 | N14: =IF($F14<0,-$F14,0) -> 0 | Q14: =C14/$O$13 -> 0.67440218 | R14: =D14/$O$13 -> 0.70578145 | S14: =IF(ISNA(D14),"",TEXT(D14,"0")) -> 6995 | T14: =E14/$O$13 -> 0.031379276 | U14: =IF(ISNA(E14),"",TEXT(E14,"+0;-0")) -> +311 | V14: =I14/$O$13 -> 0.031379276 | W14: =J14/$O$13 -> #N/A | X14: =K14/$P$13 -> 0.48352748 | Y14: =IF(ISNA(K14),"",TEXT(K14,"+0.0;-0.0")) -> +4.7 | Z14: =L14/$P$13 -> #N/A | AA14: =IF(ISNA(L14),"",TEXT(L14,"+0.0;-0.0")) | AB14: =M14/$P$13 -> 0.48352748 | AC14: =N14/$P$13 -> 0
A15: Mar | B15: AC | C15: 9041 | D15: 9911 | E15: =D15-C15 -> 870 | F15: =IF(C15<=0,NA(),(D15-C15)/C15*100) -> 9.6228293 | G15: =IF($B15="AC",$D15,NA()) -> 9911 | H15: =IF($B15="AC",NA(),$D15) -> #N/A | I15: =IF($E15>0,$E15,NA()) -> 870 | J15: =IF($E15<0,$E15,NA()) -> #N/A | K15: =IF($F15>0,$F15,NA()) -> 9.6228293 | L15: =IF($F15<0,$F15,NA()) -> #N/A | M15: =IF($F15>0,$F15,0) -> 9.6228293 | N15: =IF($F15<0,-$F15,0) -> 0 | Q15: =C15/$O$13 -> 0.91221875 | R15: =D15/$O$13 -> 1 | S15: =IF(ISNA(D15),"",TEXT(D15,"0")) -> 9911 | T15: =E15/$O$13 -> 0.087781253 | U15: =IF(ISNA(E15),"",TEXT(E15,"+0;-0")) -> +870 | V15: =I15/$O$13 -> 0.087781253 | W15: =J15/$O$13 -> #N/A | X15: =K15/$P$13 -> 1 | Y15: =IF(ISNA(K15),"",TEXT(K15,"+0.0;-0.0")) -> +9.6 | Z15: =L15/$P$13 -> #N/A | AA15: =IF(ISNA(L15),"",TEXT(L15,"+0.0;-0.0")) | AB15: =M15/$P$13 -> 1 | AC15: =N15/$P$13 -> 0
A16: Apr | B16: AC | C16: 6837 | D16: 7278 | E16: =D16-C16 -> 441 | F16: =IF(C16<=0,NA(),(D16-C16)/C16*100) -> 6.4501975 | G16: =IF($B16="AC",$D16,NA()) -> 7278 | H16: =IF($B16="AC",NA(),$D16) -> #N/A | I16: =IF($E16>0,$E16,NA()) -> 441 | J16: =IF($E16<0,$E16,NA()) -> #N/A | K16: =IF($F16>0,$F16,NA()) -> 6.4501975 | L16: =IF($F16<0,$F16,NA()) -> #N/A | M16: =IF($F16>0,$F16,0) -> 6.4501975 | N16: =IF($F16<0,-$F16,0) -> 0 | Q16: =C16/$O$13 -> 0.68983957 | R16: =D16/$O$13 -> 0.73433559 | S16: =IF(ISNA(D16),"",TEXT(D16,"0")) -> 7278 | T16: =E16/$O$13 -> 0.044496015 | U16: =IF(ISNA(E16),"",TEXT(E16,"+0;-0")) -> +441 | V16: =I16/$O$13 -> 0.044496015 | W16: =J16/$O$13 -> #N/A | X16: =K16/$P$13 -> 0.67030155 | Y16: =IF(ISNA(K16),"",TEXT(K16,"+0.0;-0.0")) -> +6.5 | Z16: =L16/$P$13 -> #N/A | AA16: =IF(ISNA(L16),"",TEXT(L16,"+0.0;-0.0")) | AB16: =M16/$P$13 -> 0.67030155 | AC16: =N16/$P$13 -> 0
A17: May | B17: AC | C17: 6634 | D17: 7027 | E17: =D17-C17 -> 393 | F17: =IF(C17<=0,NA(),(D17-C17)/C17*100) -> 5.9240277 | G17: =IF($B17="AC",$D17,NA()) -> 7027 | H17: =IF($B17="AC",NA(),$D17) -> #N/A | I17: =IF($E17>0,$E17,NA()) -> 393 | J17: =IF($E17<0,$E17,NA()) -> #N/A | K17: =IF($F17>0,$F17,NA()) -> 5.9240277 | L17: =IF($F17<0,$F17,NA()) -> #N/A | M17: =IF($F17>0,$F17,0) -> 5.9240277 | N17: =IF($F17<0,-$F17,0) -> 0 | Q17: =C17/$O$13 -> 0.66935728 | R17: =D17/$O$13 -> 0.70901019 | S17: =IF(ISNA(D17),"",TEXT(D17,"0")) -> 7027 | T17: =E17/$O$13 -> 0.039652911 | U17: =IF(ISNA(E17),"",TEXT(E17,"+0;-0")) -> +393 | V17: =I17/$O$13 -> 0.039652911 | W17: =J17/$O$13 -> #N/A | X17: =K17/$P$13 -> 0.61562224 | Y17: =IF(ISNA(K17),"",TEXT(K17,"+0.0;-0.0")) -> +5.9 | Z17: =L17/$P$13 -> #N/A | AA17: =IF(ISNA(L17),"",TEXT(L17,"+0.0;-0.0")) | AB17: =M17/$P$13 -> 0.61562224 | AC17: =N17/$P$13 -> 0
A18: Jun | B18: AC | C18: 6605 | D18: 6772 | E18: =D18-C18 -> 167 | F18: =IF(C18<=0,NA(),(D18-C18)/C18*100) -> 2.5283876 | G18: =IF($B18="AC",$D18,NA()) -> 6772 | H18: =IF($B18="AC",NA(),$D18) -> #N/A | I18: =IF($E18>0,$E18,NA()) -> 167 | J18: =IF($E18<0,$E18,NA()) -> #N/A | K18: =IF($F18>0,$F18,NA()) -> 2.5283876 | L18: =IF($F18<0,$F18,NA()) -> #N/A | M18: =IF($F18>0,$F18,0) -> 2.5283876 | N18: =IF($F18<0,-$F18,0) -> 0 | Q18: =C18/$O$13 -> 0.66643124 | R18: =D18/$O$13 -> 0.6832812 | S18: =IF(ISNA(D18),"",TEXT(D18,"0")) -> 6772 | T18: =E18/$O$13 -> 0.016849965 | U18: =IF(ISNA(E18),"",TEXT(E18,"+0;-0")) -> +167 | V18: =I18/$O$13 -> 0.016849965 | W18: =J18/$O$13 -> #N/A | X18: =K18/$P$13 -> 0.26274888 | Y18: =IF(ISNA(K18),"",TEXT(K18,"+0.0;-0.0")) -> +2.5 | Z18: =L18/$P$13 -> #N/A | AA18: =IF(ISNA(L18),"",TEXT(L18,"+0.0;-0.0")) | AB18: =M18/$P$13 -> 0.26274888 | AC18: =N18/$P$13 -> 0
A19: Jul | B19: AC | C19: 7057 | D19: 7441 | E19: =D19-C19 -> 384 | F19: =IF(C19<=0,NA(),(D19-C19)/C19*100) -> 5.4414057 | G19: =IF($B19="AC",$D19,NA()) -> 7441 | H19: =IF($B19="AC",NA(),$D19) -> #N/A | I19: =IF($E19>0,$E19,NA()) -> 384 | J19: =IF($E19<0,$E19,NA()) -> #N/A | K19: =IF($F19>0,$F19,NA()) -> 5.4414057 | L19: =IF($F19<0,$F19,NA()) -> #N/A | M19: =IF($F19>0,$F19,0) -> 5.4414057 | N19: =IF($F19<0,-$F19,0) -> 0 | Q19: =C19/$O$13 -> 0.71203713 | R19: =D19/$O$13 -> 0.75078196 | S19: =IF(ISNA(D19),"",TEXT(D19,"0")) -> 7441 | T19: =E19/$O$13 -> 0.038744829 | U19: =IF(ISNA(E19),"",TEXT(E19,"+0;-0")) -> +384 | V19: =I19/$O$13 -> 0.038744829 | W19: =J19/$O$13 -> #N/A | X19: =K19/$P$13 -> 0.56546838 | Y19: =IF(ISNA(K19),"",TEXT(K19,"+0.0;-0.0")) -> +5.4 | Z19: =L19/$P$13 -> #N/A | AA19: =IF(ISNA(L19),"",TEXT(L19,"+0.0;-0.0")) | AB19: =M19/$P$13 -> 0.56546838 | AC19: =N19/$P$13 -> 0
A20: Aug | B20: FC | C20: 7199 | D20: 7610 | E20: =D20-C20 -> 411 | F20: =IF(C20<=0,NA(),(D20-C20)/C20*100) -> 5.7091263 | G20: =IF($B20="AC",$D20,NA()) -> #N/A | H20: =IF($B20="AC",NA(),$D20) -> 7610 | I20: =IF($E20>0,$E20,NA()) -> 411 | J20: =IF($E20<0,$E20,NA()) -> #N/A | K20: =IF($F20>0,$F20,NA()) -> 5.7091263 | L20: =IF($F20<0,$F20,NA()) -> #N/A | M20: =IF($F20>0,$F20,0) -> 5.7091263 | N20: =IF($F20<0,-$F20,0) -> 0 | Q20: =C20/$O$13 -> 0.72636465 | R20: =D20/$O$13 -> 0.76783372 | S20: =IF(ISNA(D20),"",TEXT(D20,"0")) -> 7610 | T20: =E20/$O$13 -> 0.041469075 | U20: =IF(ISNA(E20),"",TEXT(E20,"+0;-0")) -> +411 | V20: =I20/$O$13 -> 0.041469075 | W20: =J20/$O$13 -> #N/A | X20: =K20/$P$13 -> 0.59328978 | Y20: =IF(ISNA(K20),"",TEXT(K20,"+0.0;-0.0")) -> +5.7 | Z20: =L20/$P$13 -> #N/A | AA20: =IF(ISNA(L20),"",TEXT(L20,"+0.0;-0.0")) | AB20: =M20/$P$13 -> 0.59328978 | AC20: =N20/$P$13 -> 0
A21: Sep | B21: FC | C21: 7128 | D21: 7535 | E21: =D21-C21 -> 407 | F21: =IF(C21<=0,NA(),(D21-C21)/C21*100) -> 5.7098765 | G21: =IF($B21="AC",$D21,NA()) -> #N/A | H21: =IF($B21="AC",NA(),$D21) -> 7535 | I21: =IF($E21>0,$E21,NA()) -> 407 | J21: =IF($E21<0,$E21,NA()) -> #N/A | K21: =IF($F21>0,$F21,NA()) -> 5.7098765 | L21: =IF($F21<0,$F21,NA()) -> #N/A | M21: =IF($F21>0,$F21,0) -> 5.7098765 | N21: =IF($F21<0,-$F21,0) -> 0 | Q21: =C21/$O$13 -> 0.71920089 | R21: =D21/$O$13 -> 0.76026637 | S21: =IF(ISNA(D21),"",TEXT(D21,"0")) -> 7535 | T21: =E21/$O$13 -> 0.041065483 | U21: =IF(ISNA(E21),"",TEXT(E21,"+0;-0")) -> +407 | V21: =I21/$O$13 -> 0.041065483 | W21: =J21/$O$13 -> #N/A | X21: =K21/$P$13 -> 0.59336775 | Y21: =IF(ISNA(K21),"",TEXT(K21,"+0.0;-0.0")) -> +5.7 | Z21: =L21/$P$13 -> #N/A | AA21: =IF(ISNA(L21),"",TEXT(L21,"+0.0;-0.0")) | AB21: =M21/$P$13 -> 0.59336775 | AC21: =N21/$P$13 -> 0
A22: Oct | B22: FC | C22: 7002 | D22: 7402 | E22: =D22-C22 -> 400 | F22: =IF(C22<=0,NA(),(D22-C22)/C22*100) -> 5.7126535 | G22: =IF($B22="AC",$D22,NA()) -> #N/A | H22: =IF($B22="AC",NA(),$D22) -> 7402 | I22: =IF($E22>0,$E22,NA()) -> 400 | J22: =IF($E22<0,$E22,NA()) -> #N/A | K22: =IF($F22>0,$F22,NA()) -> 5.7126535 | L22: =IF($F22<0,$F22,NA()) -> #N/A | M22: =IF($F22>0,$F22,0) -> 5.7126535 | N22: =IF($F22<0,-$F22,0) -> 0 | Q22: =C22/$O$13 -> 0.70648774 | R22: =D22/$O$13 -> 0.74684694 | S22: =IF(ISNA(D22),"",TEXT(D22,"0")) -> 7402 | T22: =E22/$O$13 -> 0.040359197 | U22: =IF(ISNA(E22),"",TEXT(E22,"+0;-0")) -> +400 | V22: =I22/$O$13 -> 0.040359197 | W22: =J22/$O$13 -> #N/A | X22: =K22/$P$13 -> 0.59365633 | Y22: =IF(ISNA(K22),"",TEXT(K22,"+0.0;-0.0")) -> +5.7 | Z22: =L22/$P$13 -> #N/A | AA22: =IF(ISNA(L22),"",TEXT(L22,"+0.0;-0.0")) | AB22: =M22/$P$13 -> 0.59365633 | AC22: =N22/$P$13 -> 0
A23: Nov | B23: FC | C23: 6193 | D23: 6547 | E23: =D23-C23 -> 354 | F23: =IF(C23<=0,NA(),(D23-C23)/C23*100) -> 5.7161311 | G23: =IF($B23="AC",$D23,NA()) -> #N/A | H23: =IF($B23="AC",NA(),$D23) -> 6547 | I23: =IF($E23>0,$E23,NA()) -> 354 | J23: =IF($E23<0,$E23,NA()) -> #N/A | K23: =IF($F23>0,$F23,NA()) -> 5.7161311 | L23: =IF($F23<0,$F23,NA()) -> #N/A | M23: =IF($F23>0,$F23,0) -> 5.7161311 | N23: =IF($F23<0,-$F23,0) -> 0 | Q23: =C23/$O$13 -> 0.62486127 | R23: =D23/$O$13 -> 0.66057915 | S23: =IF(ISNA(D23),"",TEXT(D23,"0")) -> 6547 | T23: =E23/$O$13 -> 0.035717889 | U23: =IF(ISNA(E23),"",TEXT(E23,"+0;-0")) -> +354 | V23: =I23/$O$13 -> 0.035717889 | W23: =J23/$O$13 -> #N/A | X23: =K23/$P$13 -> 0.59401772 | Y23: =IF(ISNA(K23),"",TEXT(K23,"+0.0;-0.0")) -> +5.7 | Z23: =L23/$P$13 -> #N/A | AA23: =IF(ISNA(L23),"",TEXT(L23,"+0.0;-0.0")) | AB23: =M23/$P$13 -> 0.59401772 | AC23: =N23/$P$13 -> 0
A24: Dec | B24: FC | C24: 6313 | D24: 6674 | E24: =D24-C24 -> 361 | F24: =IF(C24<=0,NA(),(D24-C24)/C24*100) -> 5.7183589 | G24: =IF($B24="AC",$D24,NA()) -> #N/A | H24: =IF($B24="AC",NA(),$D24) -> 6674 | I24: =IF($E24>0,$E24,NA()) -> 361 | J24: =IF($E24<0,$E24,NA()) -> #N/A | K24: =IF($F24>0,$F24,NA()) -> 5.7183589 | L24: =IF($F24<0,$F24,NA()) -> #N/A | M24: =IF($F24>0,$F24,0) -> 5.7183589 | N24: =IF($F24<0,-$F24,0) -> 0 | Q24: =C24/$O$13 -> 0.63696902 | R24: =D24/$O$13 -> 0.6733932 | S24: =IF(ISNA(D24),"",TEXT(D24,"0")) -> 6674 | T24: =E24/$O$13 -> 0.036424175 | U24: =IF(ISNA(E24),"",TEXT(E24,"+0;-0")) -> +361 | V24: =I24/$O$13 -> 0.036424175 | W24: =J24/$O$13 -> #N/A | X24: =K24/$P$13 -> 0.59424923 | Y24: =IF(ISNA(K24),"",TEXT(K24,"+0.0;-0.0")) -> +5.7 | Z24: =L24/$P$13 -> #N/A | AA24: =IF(ISNA(L24),"",TEXT(L24,"+0.0;-0.0")) | AB24: =M24/$P$13 -> 0.59424923 | AC24: =N24/$P$13 -> 0
A26: FC is not reported by the entity. Progressive publishes no forecast. Remaining months are prior-year months grown at the year-to-date pace through Jul (+5.7%). Replace these cells with your own figures and every chart on this sheet follows.

Sheet C04A
A1: Entity | B1: The Progressive Corporation
A2: Measure | B2: Underwriting result
A3: Unit | B3: $m
A4: Period | B4: 2023
A5: Reference | B5: PL
A6: Message | B6: 6 of 12 months beat the 96 combined ratio target in 2023; Dec by +670 $m and Mar missed it by 441 $m, a spread of 1,111 $m across the year
A7: Subject | B7: =B2&" in "&B3 -> Underwriting result in $m
A9: var_abs caption | B9: ="Δ"&$B$5&" "&$B$3 -> ΔPL $m
A10: var_rel caption | B10: ="Δ"&$B$5&"%" -> ΔPL%
A12: State | B12: Scenario | C12: Measure | D12: ΔPL | E12: PL | F12: ΔPL% | G12: ΔPL up | H12: ΔPL down | I12: ΔPL% up | J12: ΔPL% down | K12: up length | L12: down length | M12: span unit | N12: span rel | O12: ref scaled | P12: measure scaled | Q12: measure text | R12: var_abs scaled | S12: var_abs text | T12: abs_up scaled | U12: abs_dn scaled | V12: var_rel scaled | W12: var_rel text | X12: rel_up scaled | Y12: rel_dn scaled
A13: Dec | B13: AC | C13: 882 | D13: 670 | E13: =C13-D13 -> 212 | F13: =IF(E13<=0,NA(),D13/E13*100) -> 316.03774 | G13: =IF($D13>0,$D13,NA()) -> 670 | H13: =IF($D13<0,$D13,NA()) -> #N/A | I13: =IF($F13>0,$F13,NA()) -> 316.03774 | J13: =IF($F13<0,$F13,NA()) -> #N/A | K13: =IF($F13>0,$F13,0) -> 316.03774 | L13: =IF($F13<0,-$F13,0) -> 0 | M13: =MAX(_xlfn.AGGREGATE(4,6,E13:E31,C13:C31,D13:D31,G13:G31,H13:H31),-_xlfn.AGGREGATE(5,6,E13:E31,C13:C31,D13:D31,G13:G31,H13:H31),0.000000001) -> 882 | N13: =MAX(_xlfn.AGGREGATE(4,6,F13:F31,I13:I31,J13:J31),-_xlfn.AGGREGATE(5,6,F13:F31,I13:I31,J13:J31),0.000000001) -> 316.03774 | O13: =E13/$M$13 -> 0.24036281 | P13: =C13/$M$13 -> 1 | Q13: =IF(ISNA(C13),"",TEXT(C13,"0")) -> 882 | R13: =D13/$M$13 -> 0.75963719 | S13: =IF(ISNA(D13),"",TEXT(D13,"+0;-0")) -> +670 | T13: =G13/$M$13 -> 0.75963719 | U13: =H13/$M$13 -> #N/A | V13: =F13/$N$13 -> 1 | W13: =IF(ISNA(F13),"",TEXT(F13,"+0;-0")) -> +316 | X13: =I13/$N$13 -> 1 | Y13: =J13/$N$13 -> #N/A
A14: Nov | B14: AC | C14: 528 | D14: 325 | E14: =C14-D14 -> 203 | F14: =IF(E14<=0,NA(),D14/E14*100) -> 160.09852 | G14: =IF($D14>0,$D14,NA()) -> 325 | H14: =IF($D14<0,$D14,NA()) -> #N/A | I14: =IF($F14>0,$F14,NA()) -> 160.09852 | J14: =IF($F14<0,$F14,NA()) -> #N/A | K14: =IF($F14>0,$F14,0) -> 160.09852 | L14: =IF($F14<0,-$F14,0) -> 0 | O14: =E14/$M$13 -> 0.23015873 | P14: =C14/$M$13 -> 0.59863946 | Q14: =IF(ISNA(C14),"",TEXT(C14,"0")) -> 528 | R14: =D14/$M$13 -> 0.36848073 | S14: =IF(ISNA(D14),"",TEXT(D14,"+0;-0")) -> +325 | T14: =G14/$M$13 -> 0.36848073 | U14: =H14/$M$13 -> #N/A | V14: =F14/$N$13 -> 0.5065804 | W14: =IF(ISNA(F14),"",TEXT(F14,"+0;-0")) -> +160 | X14: =I14/$N$13 -> 0.5065804 | Y14: =J14/$N$13 -> #N/A
A15: Jul | B15: AC | C15: 531 | D15: 305 | E15: =C15-D15 -> 226 | F15: =IF(E15<=0,NA(),D15/E15*100) -> 134.95575 | G15: =IF($D15>0,$D15,NA()) -> 305 | H15: =IF($D15<0,$D15,NA()) -> #N/A | I15: =IF($F15>0,$F15,NA()) -> 134.95575 | J15: =IF($F15<0,$F15,NA()) -> #N/A | K15: =IF($F15>0,$F15,0) -> 134.95575 | L15: =IF($F15<0,-$F15,0) -> 0 | O15: =E15/$M$13 -> 0.25623583 | P15: =C15/$M$13 -> 0.60204082 | Q15: =IF(ISNA(C15),"",TEXT(C15,"0")) -> 531 | R15: =D15/$M$13 -> 0.34580499 | S15: =IF(ISNA(D15),"",TEXT(D15,"+0;-0")) -> +305 | T15: =G15/$M$13 -> 0.34580499 | U15: =H15/$M$13 -> #N/A | V15: =F15/$N$13 -> 0.42702417 | W15: =IF(ISNA(F15),"",TEXT(F15,"+0;-0")) -> +135 | X15: =I15/$N$13 -> 0.42702417 | Y15: =J15/$N$13 -> #N/A
A16: Sep | B16: AC | C16: 479 | D16: 293 | E16: =C16-D16 -> 186 | F16: =IF(E16<=0,NA(),D16/E16*100) -> 157.52688 | G16: =IF($D16>0,$D16,NA()) -> 293 | H16: =IF($D16<0,$D16,NA()) -> #N/A | I16: =IF($F16>0,$F16,NA()) -> 157.52688 | J16: =IF($F16<0,$F16,NA()) -> #N/A | K16: =IF($F16>0,$F16,0) -> 157.52688 | L16: =IF($F16<0,-$F16,0) -> 0 | O16: =E16/$M$13 -> 0.21088435 | P16: =C16/$M$13 -> 0.5430839 | Q16: =IF(ISNA(C16),"",TEXT(C16,"0")) -> 479 | R16: =D16/$M$13 -> 0.33219955 | S16: =IF(ISNA(D16),"",TEXT(D16,"+0;-0")) -> +293 | T16: =G16/$M$13 -> 0.33219955 | U16: =H16/$M$13 -> #N/A | V16: =F16/$N$13 -> 0.49844327 | W16: =IF(ISNA(F16),"",TEXT(F16,"+0;-0")) -> +158 | X16: =I16/$N$13 -> 0.49844327 | Y16: =J16/$N$13 -> #N/A
A17: Oct | B17: AC | C17: 323 | D17: 108 | E17: =C17-D17 -> 215 | F17: =IF(E17<=0,NA(),D17/E17*100) -> 50.232558 | G17: =IF($D17>0,$D17,NA()) -> 108 | H17: =IF($D17<0,$D17,NA()) -> #N/A | I17: =IF($F17>0,$F17,NA()) -> 50.232558 | J17: =IF($F17<0,$F17,NA()) -> #N/A | K17: =IF($F17>0,$F17,0) -> 50.232558 | L17: =IF($F17<0,-$F17,0) -> 0 | O17: =E17/$M$13 -> 0.24376417 | P17: =C17/$M$13 -> 0.36621315 | Q17: =IF(ISNA(C17),"",TEXT(C17,"0")) -> 323 | R17: =D17/$M$13 -> 0.12244898 | S17: =IF(ISNA(D17),"",TEXT(D17,"+0;-0")) -> +108 | T17: =G17/$M$13 -> 0.12244898 | U17: =H17/$M$13 -> #N/A | V17: =F17/$N$13 -> 0.15894481 | W17: =IF(ISNA(F17),"",TEXT(F17,"+0;-0")) -> +50 | X17: =I17/$N$13 -> 0.15894481 | Y17: =J17/$N$13 -> #N/A
A18: Feb | B18: AC | C18: 204 | D18: 37 | E18: =C18-D18 -> 167 | F18: =IF(E18<=0,NA(),D18/E18*100) -> 22.155689 | G18: =IF($D18>0,$D18,NA()) -> 37 | H18: =IF($D18<0,$D18,NA()) -> #N/A | I18: =IF($F18>0,$F18,NA()) -> 22.155689 | J18: =IF($F18<0,$F18,NA()) -> #N/A | K18: =IF($F18>0,$F18,0) -> 22.155689 | L18: =IF($F18<0,-$F18,0) -> 0 | O18: =E18/$M$13 -> 0.1893424 | P18: =C18/$M$13 -> 0.23129252 | Q18: =IF(ISNA(C18),"",TEXT(C18,"0")) -> 204 | R18: =D18/$M$13 -> 0.041950113 | S18: =IF(ISNA(D18),"",TEXT(D18,"+0;-0")) -> +37 | T18: =G18/$M$13 -> 0.041950113 | U18: =H18/$M$13 -> #N/A | V18: =F18/$N$13 -> 0.070104567 | W18: =IF(ISNA(F18),"",TEXT(F18,"+0;-0")) -> +22 | X18: =I18/$N$13 -> 0.070104567 | Y18: =J18/$N$13 -> #N/A
A19: Jan | B19: AC | C19: 202 | D19: 0 | E19: =C19-D19 -> 202 | F19: =IF(E19<=0,NA(),D19/E19*100) -> 0 | G19: =IF($D19>0,$D19,NA()) -> #N/A | H19: =IF($D19<0,$D19,NA()) -> #N/A | I19: =IF($F19>0,$F19,NA()) -> #N/A | J19: =IF($F19<0,$F19,NA()) -> #N/A | K19: =IF($F19>0,$F19,0) -> 0 | L19: =IF($F19<0,-$F19,0) -> 0 | O19: =E19/$M$13 -> 0.22902494 | P19: =C19/$M$13 -> 0.22902494 | Q19: =IF(ISNA(C19),"",TEXT(C19,"0")) -> 202 | R19: =D19/$M$13 -> 0 | S19: =IF(ISNA(D19),"",TEXT(D19,"+0;-0")) -> +0 | T19: =G19/$M$13 -> #N/A | U19: =H19/$M$13 -> #N/A | V19: =F19/$N$13 -> 0 | W19: =IF(ISNA(F19),"",TEXT(F19,"+0;-0")) -> +0 | X19: =I19/$N$13 -> #N/A | Y19: =J19/$N$13 -> #N/A
A20: Aug | B20: AC | C20: 129 | D20: -55 | E20: =C20-D20 -> 184 | F20: =IF(E20<=0,NA(),D20/E20*100) -> -29.891304 | G20: =IF($D20>0,$D20,NA()) -> #N/A | H20: =IF($D20<0,$D20,NA()) -> -55 | I20: =IF($F20>0,$F20,NA()) -> #N/A | J20: =IF($F20<0,$F20,NA()) -> -29.891304 | K20: =IF($F20>0,$F20,0) -> 0 | L20: =IF($F20<0,-$F20,0) -> 29.891304 | O20: =E20/$M$13 -> 0.20861678 | P20: =C20/$M$13 -> 0.1462585 | Q20: =IF(ISNA(C20),"",TEXT(C20,"0")) -> 129 | R20: =D20/$M$13 -> -0.062358277 | S20: =IF(ISNA(D20),"",TEXT(D20,"+0;-0")) -> -55 | T20: =G20/$M$13 -> #N/A | U20: =H20/$M$13 -> -0.062358277 | V20: =F20/$N$13 -> -0.094581441 | W20: =IF(ISNA(F20),"",TEXT(F20,"+0;-0")) -> -30 | X20: =I20/$N$13 -> #N/A | Y20: =J20/$N$13 -> -0.094581441
A21: Apr | B21: AC | C21: 115 | D21: -103 | E21: =C21-D21 -> 218 | F21: =IF(E21<=0,NA(),D21/E21*100) -> -47.247706 | G21: =IF($D21>0,$D21,NA()) -> #N/A | H21: =IF($D21<0,$D21,NA()) -> -103 | I21: =IF($F21>0,$F21,NA()) -> #N/A | J21: =IF($F21<0,$F21,NA()) -> -47.247706 | K21: =IF($F21>0,$F21,0) -> 0 | L21: =IF($F21<0,-$F21,0) -> 47.247706 | O21: =E21/$M$13 -> 0.24716553 | P21: =C21/$M$13 -> 0.13038549 | Q21: =IF(ISNA(C21),"",TEXT(C21,"0")) -> 115 | R21: =D21/$M$13 -> -0.11678005 | S21: =IF(ISNA(D21),"",TEXT(D21,"+0;-0")) -> -103 | T21: =G21/$M$13 -> #N/A | U21: =H21/$M$13 -> -0.11678005 | V21: =F21/$N$13 -> -0.14950021 | W21: =IF(ISNA(F21),"",TEXT(F21,"+0;-0")) -> -47 | X21: =I21/$N$13 -> #N/A | Y21: =J21/$N$13 -> -0.14950021
A22: May | B22: AC | C22: 45 | D22: -135 | E22: =C22-D22 -> 180 | F22: =IF(E22<=0,NA(),D22/E22*100) -> -75 | G22: =IF($D22>0,$D22,NA()) -> #N/A | H22: =IF($D22<0,$D22,NA()) -> -135 | I22: =IF($F22>0,$F22,NA()) -> #N/A | J22: =IF($F22<0,$F22,NA()) -> -75 | K22: =IF($F22>0,$F22,0) -> 0 | L22: =IF($F22<0,-$F22,0) -> 75 | O22: =E22/$M$13 -> 0.20408163 | P22: =C22/$M$13 -> 0.051020408 | Q22: =IF(ISNA(C22),"",TEXT(C22,"0")) -> 45 | R22: =D22/$M$13 -> -0.15306122 | S22: =IF(ISNA(D22),"",TEXT(D22,"+0;-0")) -> -135 | T22: =G22/$M$13 -> #N/A | U22: =H22/$M$13 -> -0.15306122 | V22: =F22/$N$13 -> -0.23731343 | W22: =IF(ISNA(F22),"",TEXT(F22,"+0;-0")) -> -75 | X22: =I22/$N$13 -> #N/A | Y22: =J22/$N$13 -> -0.23731343
A23: Jun | B23: AC | C23: -221 | D23: -402 | E23: =C23-D23 -> 181 | F23: =IF(E23<=0,NA(),D23/E23*100) -> -222.09945 | G23: =IF($D23>0,$D23,NA()) -> #N/A | H23: =IF($D23<0,$D23,NA()) -> -402 | I23: =IF($F23>0,$F23,NA()) -> #N/A | J23: =IF($F23<0,$F23,NA()) -> -222.09945 | K23: =IF($F23>0,$F23,0) -> 0 | L23: =IF($F23<0,-$F23,0) -> 222.09945 | O23: =E23/$M$13 -> 0.20521542 | P23: =C23/$M$13 -> -0.25056689 | Q23: =IF(ISNA(C23),"",TEXT(C23,"0")) -> -221 | R23: =D23/$M$13 -> -0.45578231 | S23: =IF(ISNA(D23),"",TEXT(D23,"+0;-0")) -> -402 | T23: =G23/$M$13 -> #N/A | U23: =H23/$M$13 -> -0.45578231 | V23: =F23/$N$13 -> -0.70276243 | W23: =IF(ISNA(F23),"",TEXT(F23,"+0;-0")) -> -222 | X23: =I23/$N$13 -> #N/A | Y23: =J23/$N$13 -> -0.70276243
A24: Mar | B24: AC | C24: -268 | D24: -441 | E24: =C24-D24 -> 173 | F24: =IF(E24<=0,NA(),D24/E24*100) -> -254.91329 | G24: =IF($D24>0,$D24,NA()) -> #N/A | H24: =IF($D24<0,$D24,NA()) -> -441 | I24: =IF($F24>0,$F24,NA()) -> #N/A | J24: =IF($F24<0,$F24,NA()) -> -254.91329 | K24: =IF($F24>0,$F24,0) -> 0 | L24: =IF($F24<0,-$F24,0) -> 254.91329 | O24: =E24/$M$13 -> 0.19614512 | P24: =C24/$M$13 -> -0.30385488 | Q24: =IF(ISNA(C24),"",TEXT(C24,"0")) -> -268 | R24: =D24/$M$13 -> -0.5 | S24: =IF(ISNA(D24),"",TEXT(D24,"+0;-0")) -> -441 | T24: =G24/$M$13 -> #N/A | U24: =H24/$M$13 -> -0.5 | V24: =F24/$N$13 -> -0.80659132 | W24: =IF(ISNA(F24),"",TEXT(F24,"+0;-0")) -> -255 | X24: =I24/$N$13 -> #N/A | Y24: =J24/$N$13 -> -0.80659132
A26: PL is not reported by the entity. Progressive publishes no monthly plan. The target it does publish is a 96 combined ratio - a 4% underwriting margin - applied here to each month's earned premium. Replace these cells with your own figures and every chart on this sheet follows.

Sheet C05X
A1: Entity | B1: The Progressive Corporation
A2: Measure | B2: Underwriting result
A3: Unit | B3: $m
A4: Period | B4: 2026
A5: Reference | B5: PY
A6: Message | B6: The underwriting result is running +1,200 $m (+11.7%) ahead of 2025, with 7 of twelve months up and Sep contributing +985 on its own. Both years sit far above the 96 combined ratio target, drawn as the second opening column
A7: Subject | B7: =B2&" in "&B3 -> Underwriting result in $m
A9: var_rel caption | B9: ="Δ"&$B$5&"%" -> ΔPY%
A11: Period | B11: Scenario | C11: Kind | D11: AC/FC | E11: ΔPY | F11: PY | G11: ΔPY% | H11: PY bar | I11: PY bar | J11: AC bar | K11: FC bar | L11: level | M11: from | N11: base | O11: up AC | P11: down AC | Q11: up FC | R11: down FC | S11: ΔPY% up | T11: ΔPY% down | U11: up length | V11: down length | W11: span unit | X11: span rel | Y11: bar_py scaled | Z11: bar_py text | AA11: bar_pl scaled | AB11: bar_pl text | AC11: bar_ac scaled | AD11: bar_ac text | AE11: bar_fc scaled | AF11: bar_fc text | AG11: wf_base scaled | AH11: wf_up_ac scaled | AI11: wf_up_ac text | AJ11: wf_dn_ac scaled | AK11: wf_dn_ac text | AL11: wf_up_fc scaled | AM11: wf_up_fc text | AN11: wf_dn_fc scaled | AO11: wf_dn_fc text | AP11: rel_up scaled | AQ11: rel_up text | AR11: rel_dn scaled | AS11: rel_dn text | AT11: rel_up_len scaled | AU11: rel_dn_len scaled
A12: 2026 PL | B12: PL | C12: total | D12: =SUM(F14:F25) -> 10256 | F12: =0 -> 0 | G12: =NA() -> #N/A | H12: =NA() -> #N/A | I12: =D12 -> 10256 | J12: =NA() -> #N/A | K12: =NA() -> #N/A | L12: =0 -> 0 | M12: =L12 -> 0 | N12: =0 -> 0 | O12: =0 -> 0 | P12: =0 -> 0 | Q12: =0 -> 0 | R12: =0 -> 0 | S12: =NA() -> #N/A | T12: =NA() -> #N/A | U12: =0 -> 0 | V12: =0 -> 0 | W12: =MAX(_xlfn.AGGREGATE(4,6,H12:H28,I12:I28,J12:J28,K12:K28,N12:N28,O12:O28,P12:P28,Q12:Q28,R12:R28),-_xlfn.AGGREGATE(5,6,H12:H28,I12:I28,J12:J28,K12:K28,N12:N28,O12:O28,P12:P28,Q12:Q28,R12:R28),0.000000001) -> 11376 | X12: =MAX(_xlfn.AGGREGATE(4,6,S12:S28,T12:T28,U12:U28,V12:V28),-_xlfn.AGGREGATE(5,6,S12:S28,T12:T28,U12:U28,V12:V28),0.000000001) -> 3648.1481 | Y12: =H12/$W$12 -> #N/A | Z12: =IF(ISNA(H12),"",TEXT(H12,"#,##0")) | AA12: =I12/$W$12 -> 0.90154712 | AB12: =IF(ISNA(I12),"",TEXT(I12,"#,##0")) -> 10,256 | AC12: =J12/$W$12 -> #N/A | AD12: =IF(ISNA(J12),"",TEXT(J12,"#,##0")) | AE12: =K12/$W$12 -> #N/A | AF12: =IF(ISNA(K12),"",TEXT(K12,"#,##0")) | AG12: =N12/$W$12 -> 0 | AH12: =O12/$W$12 -> 0 | AI12: =IF(ISNA(O12),"",TEXT(O12,"+#,##0")) -> +0 | AJ12: =P12/$W$12 -> 0 | AK12: =IF(ISNA(P12),"",TEXT(P12,"""-""#,##0")) -> -0 | AL12: =Q12/$W$12 -> 0 | AM12: =IF(ISNA(Q12),"",TEXT(Q12,"+#,##0")) -> +0 | AN12: =R12/$W$12 -> 0 | AO12: =IF(ISNA(R12),"",TEXT(R12,"""-""#,##0")) -> -0 | AP12: =S12/$X$12 -> #N/A | AQ12: =IF(ISNA(S12),"",TEXT(S12,"+0.0;-0.0")) | AR12: =T12/$X$12 -> #N/A | AS12: =IF(ISNA(T12),"",TEXT(T12,"+0.0;-0.0")) | AT12: =U12/$X$12 -> 0 | AU12: =V12/$X$12 -> 0
A13: 2025 AC | B13: PY | C13: total | D13: 10256 | F13: =0 -> 0 | G13: =NA() -> #N/A | H13: =D13 -> 10256 | I13: =NA() -> #N/A | J13: =NA() -> #N/A | K13: =NA() -> #N/A | L13: =D13 -> 10256 | M13: =L13 -> 10256 | N13: =0 -> 0 | O13: =0 -> 0 | P13: =0 -> 0 | Q13: =0 -> 0 | R13: =0 -> 0 | S13: =NA() -> #N/A | T13: =NA() -> #N/A | U13: =0 -> 0 | V13: =0 -> 0 | Y13: =H13/$W$12 -> 0.90154712 | Z13: =IF(ISNA(H13),"",TEXT(H13,"#,##0")) -> 10,256 | AA13: =I13/$W$12 -> #N/A | AB13: =IF(ISNA(I13),"",TEXT(I13,"#,##0")) | AC13: =J13/$W$12 -> #N/A | AD13: =IF(ISNA(J13),"",TEXT(J13,"#,##0")) | AE13: =K13/$W$12 -> #N/A | AF13: =IF(ISNA(K13),"",TEXT(K13,"#,##0")) | AG13: =N13/$W$12 -> 0 | AH13: =O13/$W$12 -> 0 | AI13: =IF(ISNA(O13),"",TEXT(O13,"+#,##0")) -> +0 | AJ13: =P13/$W$12 -> 0 | AK13: =IF(ISNA(P13),"",TEXT(P13,"""-""#,##0")) -> -0 | AL13: =Q13/$W$12 -> 0 | AM13: =IF(ISNA(Q13),"",TEXT(Q13,"+#,##0")) -> +0 | AN13: =R13/$W$12 -> 0 | AO13: =IF(ISNA(R13),"",TEXT(R13,"""-""#,##0")) -> -0 | AP13: =S13/$X$12 -> #N/A | AQ13: =IF(ISNA(S13),"",TEXT(S13,"+0.0;-0.0")) | AR13: =T13/$X$12 -> #N/A | AS13: =IF(ISNA(T13),"",TEXT(T13,"+0.0;-0.0")) | AT13: =U13/$X$12 -> 0 | AU13: =V13/$X$12 -> 0
A14: Jan | B14: AC | C14: state | D14: 1080 | E14: 33 | F14: =D14-E14 -> 1047 | G14: =IF(F14=0,NA(),E14/F14*100) -> 3.1518625 | H14: =NA() -> #N/A | I14: =F14 -> 1047 | J14: =IF($B14="AC",D14,NA()) -> 1080 | K14: =IF($B14="FC",D14,NA()) -> #N/A | L14: =M14+E14 -> 10289 | M14: =L13 -> 10256 | N14: =MIN(M14,L14) -> 10256 | O14: =IF(AND($B14="AC",E14>0),E14,0) -> 33 | P14: =IF(AND($B14="AC",E14<0),-E14,0) -> 0 | Q14: =IF(AND($B14="FC",E14>0),E14,0) -> 0 | R14: =IF(AND($B14="FC",E14<0),-E14,0) -> 0 | S14: =IF(G14>0,G14,NA()) -> 3.1518625 | T14: =IF(G14<0,G14,NA()) -> #N/A | U14: =IF(G14>0,G14,0) -> 3.1518625 | V14: =IF(G14<0,-G14,0) -> 0 | Y14: =H14/$W$12 -> #N/A | Z14: =IF(ISNA(H14),"",TEXT(H14,"#,##0")) | AA14: =I14/$W$12 -> 0.092035865 | AB14: =IF(ISNA(I14),"",TEXT(I14,"#,##0")) -> 1,047 | AC14: =J14/$W$12 -> 0.094936709 | AD14: =IF(ISNA(J14),"",TEXT(J14,"#,##0")) -> 1,080 | AE14: =K14/$W$12 -> #N/A | AF14: =IF(ISNA(K14),"",TEXT(K14,"#,##0")) | AG14: =N14/$W$12 -> 0.90154712 | AH14: =O14/$W$12 -> 0.0029008439 | AI14: =IF(ISNA(O14),"",TEXT(O14,"+#,##0")) -> +33 | AJ14: =P14/$W$12 -> 0 | AK14: =IF(ISNA(P14),"",TEXT(P14,"""-""#,##0")) -> -0 | AL14: =Q14/$W$12 -> 0 | AM14: =IF(ISNA(Q14),"",TEXT(Q14,"+#,##0")) -> +0 | AN14: =R14/$W$12 -> 0 | AO14: =IF(ISNA(R14),"",TEXT(R14,"""-""#,##0")) -> -0 | AP14: =S14/$X$12 -> 0.0008639623 | AQ14: =IF(ISNA(S14),"",TEXT(S14,"+0.0;-0.0")) -> +3.2 | AR14: =T14/$X$12 -> #N/A | AS14: =IF(ISNA(T14),"",TEXT(T14,"+0.0;-0.0")) | AT14: =U14/$X$12 -> 0.0008639623 | AU14: =V14/$X$12 -> 0
A15: Feb | B15: AC | C15: state | D15: 934 | E15: -116 | F15: =D15-E15 -> 1050 | G15: =IF(F15=0,NA(),E15/F15*100) -> -11.047619 | H15: =NA() -> #N/A | I15: =F15 -> 1050 | J15: =IF($B15="AC",D15,NA()) -> 934 | K15: =IF($B15="FC",D15,NA()) -> #N/A | L15: =M15+E15 -> 10173 | M15: =L14 -> 10289 | N15: =MIN(M15,L15) -> 10173 | O15: =IF(AND($B15="AC",E15>0),E15,0) -> 0 | P15: =IF(AND($B15="AC",E15<0),-E15,0) -> 116 | Q15: =IF(AND($B15="FC",E15>0),E15,0) -> 0 | R15: =IF(AND($B15="FC",E15<0),-E15,0) -> 0 | S15: =IF(G15>0,G15,NA()) -> #N/A | T15: =IF(G15<0,G15,NA()) -> -11.047619 | U15: =IF(G15>0,G15,0) -> 0 | V15: =IF(G15<0,-G15,0) -> 11.047619 | Y15: =H15/$W$12 -> #N/A | Z15: =IF(ISNA(H15),"",TEXT(H15,"#,##0")) | AA15: =I15/$W$12 -> 0.092299578 | AB15: =IF(ISNA(I15),"",TEXT(I15,"#,##0")) -> 1,050 | AC15: =J15/$W$12 -> 0.082102672 | AD15: =IF(ISNA(J15),"",TEXT(J15,"#,##0")) -> 934 | AE15: =K15/$W$12 -> #N/A | AF15: =IF(ISNA(K15),"",TEXT(K15,"#,##0")) | AG15: =N15/$W$12 -> 0.89425105 | AH15: =O15/$W$12 -> 0 | AI15: =IF(ISNA(O15),"",TEXT(O15,"+#,##0")) -> +0 | AJ15: =P15/$W$12 -> 0.010196906 | AK15: =IF(ISNA(P15),"",TEXT(P15,"""-""#,##0")) -> -116 | AL15: =Q15/$W$12 -> 0 | AM15: =IF(ISNA(Q15),"",TEXT(Q15,"+#,##0")) -> +0 | AN15: =R15/$W$12 -> 0 | AO15: =IF(ISNA(R15),"",TEXT(R15,"""-""#,##0")) -> -0 | AP15: =S15/$X$12 -> #N/A | AQ15: =IF(ISNA(S15),"",TEXT(S15,"+0.0;-0.0")) | AR15: =T15/$X$12 -> -0.0030282814 | AS15: =IF(ISNA(T15),"",TEXT(T15,"+0.0;-0.0")) -> -11.0 | AT15: =U15/$X$12 -> 0 | AU15: =V15/$X$12 -> 0.0030282814
A16: Mar | B16: AC | C16: state | D16: 842 | E16: 224 | F16: =D16-E16 -> 618 | G16: =IF(F16=0,NA(),E16/F16*100) -> 36.245955 | H16: =NA() -> #N/A | I16: =F16 -> 618 | J16: =IF($B16="AC",D16,NA()) -> 842 | K16: =IF($B16="FC",D16,NA()) -> #N/A | L16: =M16+E16 -> 10397 | M16: =L15 -> 10173 | N16: =MIN(M16,L16) -> 10173 | O16: =IF(AND($B16="AC",E16>0),E16,0) -> 224 | P16: =IF(AND($B16="AC",E16<0),-E16,0) -> 0 | Q16: =IF(AND($B16="FC",E16>0),E16,0) -> 0 | R16: =IF(AND($B16="FC",E16<0),-E16,0) -> 0 | S16: =IF(G16>0,G16,NA()) -> 36.245955 | T16: =IF(G16<0,G16,NA()) -> #N/A | U16: =IF(G16>0,G16,0) -> 36.245955 | V16: =IF(G16<0,-G16,0) -> 0 | Y16: =H16/$W$12 -> #N/A | Z16: =IF(ISNA(H16),"",TEXT(H16,"#,##0")) | AA16: =I16/$W$12 -> 0.054324895 | AB16: =IF(ISNA(I16),"",TEXT(I16,"#,##0")) -> 618 | AC16: =J16/$W$12 -> 0.074015471 | AD16: =IF(ISNA(J16),"",TEXT(J16,"#,##0")) -> 842 | AE16: =K16/$W$12 -> #N/A | AF16: =IF(ISNA(K16),"",TEXT(K16,"#,##0")) | AG16: =N16/$W$12 -> 0.89425105 | AH16: =O16/$W$12 -> 0.019690577 | AI16: =IF(ISNA(O16),"",TEXT(O16,"+#,##0")) -> +224 | AJ16: =P16/$W$12 -> 0 | AK16: =IF(ISNA(P16),"",TEXT(P16,"""-""#,##0")) -> -0 | AL16: =Q16/$W$12 -> 0 | AM16: =IF(ISNA(Q16),"",TEXT(Q16,"+#,##0")) -> +0 | AN16: =R16/$W$12 -> 0 | AO16: =IF(ISNA(R16),"",TEXT(R16,"""-""#,##0")) -> -0 | AP16: =S16/$X$12 -> 0.0099354394 | AQ16: =IF(ISNA(S16),"",TEXT(S16,"+0.0;-0.0")) -> +36.2 | AR16: =T16/$X$12 -> #N/A | AS16: =IF(ISNA(T16),"",TEXT(T16,"+0.0;-0.0")) | AT16: =U16/$X$12 -> 0.0099354394 | AU16: =V16/$X$12 -> 0
A17: Apr | B17: AC | C17: state | D17: 697 | E17: -306 | F17: =D17-E17 -> 1003 | G17: =IF(F17=0,NA(),E17/F17*100) -> -30.508475 | H17: =NA() -> #N/A | I17: =F17 -> 1003 | J17: =IF($B17="AC",D17,NA()) -> 697 | K17: =IF($B17="FC",D17,NA()) -> #N/A | L17: =M17+E17 -> 10091 | M17: =L16 -> 10397 | N17: =MIN(M17,L17) -> 10091 | O17: =IF(AND($B17="AC",E17>0),E17,0) -> 0 | P17: =IF(AND($B17="AC",E17<0),-E17,0) -> 306 | Q17: =IF(AND($B17="FC",E17>0),E17,0) -> 0 | R17: =IF(AND($B17="FC",E17<0),-E17,0) -> 0 | S17: =IF(G17>0,G17,NA()) -> #N/A | T17: =IF(G17<0,G17,NA()) -> -30.508475 | U17: =IF(G17>0,G17,0) -> 0 | V17: =IF(G17<0,-G17,0) -> 30.508475 | Y17: =H17/$W$12 -> #N/A | Z17: =IF(ISNA(H17),"",TEXT(H17,"#,##0")) | AA17: =I17/$W$12 -> 0.088168073 | AB17: =IF(ISNA(I17),"",TEXT(I17,"#,##0")) -> 1,003 | AC17: =J17/$W$12 -> 0.061269339 | AD17: =IF(ISNA(J17),"",TEXT(J17,"#,##0")) -> 697 | AE17: =K17/$W$12 -> #N/A | AF17: =IF(ISNA(K17),"",TEXT(K17,"#,##0")) | AG17: =N17/$W$12 -> 0.8870429 | AH17: =O17/$W$12 -> 0 | AI17: =IF(ISNA(O17),"",TEXT(O17,"+#,##0")) -> +0 | AJ17: =P17/$W$12 -> 0.026898734 | AK17: =IF(ISNA(P17),"",TEXT(P17,"""-""#,##0")) -> -306 | AL17: =Q17/$W$12 -> 0 | AM17: =IF(ISNA(Q17),"",TEXT(Q17,"+#,##0")) -> +0 | AN17: =R17/$W$12 -> 0 | AO17: =IF(ISNA(R17),"",TEXT(R17,"""-""#,##0")) -> -0 | AP17: =S17/$X$12 -> #N/A | AQ17: =IF(ISNA(S17),"",TEXT(S17,"+0.0;-0.0")) | AR17: =T17/$X$12 -> -0.0083627291 | AS17: =IF(ISNA(T17),"",TEXT(T17,"+0.0;-0.0")) -> -30.5 | AT17: =U17/$X$12 -> 0 | AU17: =V17/$X$12 -> 0.0083627291
A18: May | B18: AC | C18: state | D18: 1318 | E18: 438 | F18: =D18-E18 -> 880 | G18: =IF(F18=0,NA(),E18/F18*100) -> 49.772727 | H18: =NA() -> #N/A | I18: =F18 -> 880 | J18: =IF($B18="AC",D18,NA()) -> 1318 | K18: =IF($B18="FC",D18,NA()) -> #N/A | L18: =M18+E18 -> 10529 | M18: =L17 -> 10091 | N18: =MIN(M18,L18) -> 10091 | O18: =IF(AND($B18="AC",E18>0),E18,0) -> 438 | P18: =IF(AND($B18="AC",E18<0),-E18,0) -> 0 | Q18: =IF(AND($B18="FC",E18>0),E18,0) -> 0 | R18: =IF(AND($B18="FC",E18<0),-E18,0) -> 0 | S18: =IF(G18>0,G18,NA()) -> 49.772727 | T18: =IF(G18<0,G18,NA()) -> #N/A | U18: =IF(G18>0,G18,0) -> 49.772727 | V18: =IF(G18<0,-G18,0) -> 0 | Y18: =H18/$W$12 -> #N/A | Z18: =IF(ISNA(H18),"",TEXT(H18,"#,##0")) | AA18: =I18/$W$12 -> 0.077355837 | AB18: =IF(ISNA(I18),"",TEXT(I18,"#,##0")) -> 880 | AC18: =J18/$W$12 -> 0.11585795 | AD18: =IF(ISNA(J18),"",TEXT(J18,"#,##0")) -> 1,318 | AE18: =K18/$W$12 -> #N/A | AF18: =IF(ISNA(K18),"",TEXT(K18,"#,##0")) | AG18: =N18/$W$12 -> 0.8870429 | AH18: =O18/$W$12 -> 0.03850211 | AI18: =IF(ISNA(O18),"",TEXT(O18,"+#,##0")) -> +438 | AJ18: =P18/$W$12 -> 0 | AK18: =IF(ISNA(P18),"",TEXT(P18,"""-""#,##0")) -> -0 | AL18: =Q18/$W$12 -> 0 | AM18: =IF(ISNA(Q18),"",TEXT(Q18,"+#,##0")) -> +0 | AN18: =R18/$W$12 -> 0 | AO18: =IF(ISNA(R18),"",TEXT(R18,"""-""#,##0")) -> -0 | AP18: =S18/$X$12 -> 0.013643286 | AQ18: =IF(ISNA(S18),"",TEXT(S18,"+0.0;-0.0")) -> +49.8 | AR18: =T18/$X$12 -> #N/A | AS18: =IF(ISNA(T18),"",TEXT(T18,"+0.0;-0.0")) | AT18: =U18/$X$12 -> 0.013643286 | AU18: =V18/$X$12 -> 0
A19: Jun | B19: AC | C19: state | D19: 710 | E19: -222 | F19: =D19-E19 -> 932 | G19: =IF(F19=0,NA(),E19/F19*100) -> -23.819742 | H19: =NA() -> #N/A | I19: =F19 -> 932 | J19: =IF($B19="AC",D19,NA()) -> 710 | K19: =IF($B19="FC",D19,NA()) -> #N/A | L19: =M19+E19 -> 10307 | M19: =L18 -> 10529 | N19: =MIN(M19,L19) -> 10307 | O19: =IF(AND($B19="AC",E19>0),E19,0) -> 0 | P19: =IF(AND($B19="AC",E19<0),-E19,0) -> 222 | Q19: =IF(AND($B19="FC",E19>0),E19,0) -> 0 | R19: =IF(AND($B19="FC",E19<0),-E19,0) -> 0 | S19: =IF(G19>0,G19,NA()) -> #N/A | T19: =IF(G19<0,G19,NA()) -> -23.819742 | U19: =IF(G19>0,G19,0) -> 0 | V19: =IF(G19<0,-G19,0) -> 23.819742 | Y19: =H19/$W$12 -> #N/A | Z19: =IF(ISNA(H19),"",TEXT(H19,"#,##0")) | AA19: =I19/$W$12 -> 0.081926864 | AB19: =IF(ISNA(I19),"",TEXT(I19,"#,##0")) -> 932 | AC19: =J19/$W$12 -> 0.062412096 | AD19: =IF(ISNA(J19),"",TEXT(J19,"#,##0")) -> 710 | AE19: =K19/$W$12 -> #N/A | AF19: =IF(ISNA(K19),"",TEXT(K19,"#,##0")) | AG19: =N19/$W$12 -> 0.90603024 | AH19: =O19/$W$12 -> 0 | AI19: =IF(ISNA(O19),"",TEXT(O19,"+#,##0")) -> +0 | AJ19: =P19/$W$12 -> 0.019514768 | AK19: =IF(ISNA(P19),"",TEXT(P19,"""-""#,##0")) -> -222 | AL19: =Q19/$W$12 -> 0 | AM19: =IF(ISNA(Q19),"",TEXT(Q19,"+#,##0")) -> +0 | AN19: =R19/$W$12 -> 0 | AO19: =IF(ISNA(R19),"",TEXT(R19,"""-""#,##0")) -> -0 | AP19: =S19/$X$12 -> #N/A | AQ19: =IF(ISNA(S19),"",TEXT(S19,"+0.0;-0.0")) | AR19: =T19/$X$12 -> -0.0065292695 | AS19: =IF(ISNA(T19),"",TEXT(T19,"+0.0;-0.0")) -> -23.8 | AT19: =U19/$X$12 -> 0 | AU19: =V19/$X$12 -> 0.0065292695
A20: Jul | B20: AC | C20: state | D20: 971 | E20: -56 | F20: =D20-E20 -> 1027 | G20: =IF(F20=0,NA(),E20/F20*100) -> -5.4527751 | H20: =NA() -> #N/A | I20: =F20 -> 1027 | J20: =IF($B20="AC",D20,NA()) -> 971 | K20: =IF($B20="FC",D20,NA()) -> #N/A | L20: =M20+E20 -> 10251 | M20: =L19 -> 10307 | N20: =MIN(M20,L20) -> 10251 | O20: =IF(AND($B20="AC",E20>0),E20,0) -> 0 | P20: =IF(AND($B20="AC",E20<0),-E20,0) -> 56 | Q20: =IF(AND($B20="FC",E20>0),E20,0) -> 0 | R20: =IF(AND($B20="FC",E20<0),-E20,0) -> 0 | S20: =IF(G20>0,G20,NA()) -> #N/A | T20: =IF(G20<0,G20,NA()) -> -5.4527751 | U20: =IF(G20>0,G20,0) -> 0 | V20: =IF(G20<0,-G20,0) -> 5.4527751 | Y20: =H20/$W$12 -> #N/A | Z20: =IF(ISNA(H20),"",TEXT(H20,"#,##0")) | AA20: =I20/$W$12 -> 0.090277778 | AB20: =IF(ISNA(I20),"",TEXT(I20,"#,##0")) -> 1,027 | AC20: =J20/$W$12 -> 0.085355134 | AD20: =IF(ISNA(J20),"",TEXT(J20,"#,##0")) -> 971 | AE20: =K20/$W$12 -> #N/A | AF20: =IF(ISNA(K20),"",TEXT(K20,"#,##0")) | AG20: =N20/$W$12 -> 0.90110759 | AH20: =O20/$W$12 -> 0 | AI20: =IF(ISNA(O20),"",TEXT(O20,"+#,##0")) -> +0 | AJ20: =P20/$W$12 -> 0.0049226442 | AK20: =IF(ISNA(P20),"",TEXT(P20,"""-""#,##0")) -> -56 | AL20: =Q20/$W$12 -> 0 | AM20: =IF(ISNA(Q20),"",TEXT(Q20,"+#,##0")) -> +0 | AN20: =R20/$W$12 -> 0 | AO20: =IF(ISNA(R20),"",TEXT(R20,"""-""#,##0")) -> -0 | AP20: =S20/$X$12 -> #N/A | AQ20: =IF(ISNA(S20),"",TEXT(S20,"+0.0;-0.0")) | AR20: =T20/$X$12 -> -0.0014946693 | AS20: =IF(ISNA(T20),"",TEXT(T20,"+0.0;-0.0")) -> -5.5 | AT20: =U20/$X$12 -> 0 | AU20: =V20/$X$12 -> 0.0014946693
A21: Aug | B21: FC | C21: state | D21: 987 | E21: -202 | F21: =D21-E21 -> 1189 | G21: =IF(F21=0,NA(),E21/F21*100) -> -16.989066 | H21: =NA() -> #N/A | I21: =F21 -> 1189 | J21: =IF($B21="AC",D21,NA()) -> #N/A | K21: =IF($B21="FC",D21,NA()) -> 987 | L21: =M21+E21 -> 10049 | M21: =L20 -> 10251 | N21: =MIN(M21,L21) -> 10049 | O21: =IF(AND($B21="AC",E21>0),E21,0) -> 0 | P21: =IF(AND($B21="AC",E21<0),-E21,0) -> 0 | Q21: =IF(AND($B21="FC",E21>0),E21,0) -> 0 | R21: =IF(AND($B21="FC",E21<0),-E21,0) -> 202 | S21: =IF(G21>0,G21,NA()) -> #N/A | T21: =IF(G21<0,G21,NA()) -> -16.989066 | U21: =IF(G21>0,G21,0) -> 0 | V21: =IF(G21<0,-G21,0) -> 16.989066 | Y21: =H21/$W$12 -> #N/A | Z21: =IF(ISNA(H21),"",TEXT(H21,"#,##0")) | AA21: =I21/$W$12 -> 0.10451828 | AB21: =IF(ISNA(I21),"",TEXT(I21,"#,##0")) -> 1,189 | AC21: =J21/$W$12 -> #N/A | AD21: =IF(ISNA(J21),"",TEXT(J21,"#,##0")) | AE21: =K21/$W$12 -> 0.086761603 | AF21: =IF(ISNA(K21),"",TEXT(K21,"#,##0")) -> 987 | AG21: =N21/$W$12 -> 0.88335091 | AH21: =O21/$W$12 -> 0 | AI21: =IF(ISNA(O21),"",TEXT(O21,"+#,##0")) -> +0 | AJ21: =P21/$W$12 -> 0 | AK21: =IF(ISNA(P21),"",TEXT(P21,"""-""#,##0")) -> -0 | AL21: =Q21/$W$12 -> 0 | AM21: =IF(ISNA(Q21),"",TEXT(Q21,"+#,##0")) -> +0 | AN21: =R21/$W$12 -> 0.017756681 | AO21: =IF(ISNA(R21),"",TEXT(R21,"""-""#,##0")) -> -202 | AP21: =S21/$X$12 -> #N/A | AQ21: =IF(ISNA(S21),"",TEXT(S21,"+0.0;-0.0")) | AR21: =T21/$X$12 -> -0.0046569015 | AS21: =IF(ISNA(T21),"",TEXT(T21,"+0.0;-0.0")) -> -17.0 | AT21: =U21/$X$12 -> 0 | AU21: =V21/$X$12 -> 0.0046569015
A22: Sep | B22: FC | C22: state | D22: 958 | E22: 985 | F22: =D22-E22 -> -27 | G22: =IF(F22=0,NA(),E22/F22*100) -> -3648.1481 | H22: =NA() -> #N/A | I22: =F22 -> -27 | J22: =IF($B22="AC",D22,NA()) -> #N/A | K22: =IF($B22="FC",D22,NA()) -> 958 | L22: =M22+E22 -> 11034 | M22: =L21 -> 10049 | N22: =MIN(M22,L22) -> 10049 | O22: =IF(AND($B22="AC",E22>0),E22,0) -> 0 | P22: =IF(AND($B22="AC",E22<0),-E22,0) -> 0 | Q22: =IF(AND($B22="FC",E22>0),E22,0) -> 985 | R22: =IF(AND($B22="FC",E22<0),-E22,0) -> 0 | S22: =IF(G22>0,G22,NA()) -> #N/A | T22: =IF(G22<0,G22,NA()) -> -3648.1481 | U22: =IF(G22>0,G22,0) -> 0 | V22: =IF(G22<0,-G22,0) -> 3648.1481 | Y22: =H22/$W$12 -> #N/A | Z22: =IF(ISNA(H22),"",TEXT(H22,"#,##0")) | AA22: =I22/$W$12 -> -0.0023734177 | AB22: =IF(ISNA(I22),"",TEXT(I22,"#,##0")) -> -27 | AC22: =J22/$W$12 -> #N/A | AD22: =IF(ISNA(J22),"",TEXT(J22,"#,##0")) | AE22: =K22/$W$12 -> 0.084212377 | AF22: =IF(ISNA(K22),"",TEXT(K22,"#,##0")) -> 958 | AG22: =N22/$W$12 -> 0.88335091 | AH22: =O22/$W$12 -> 0 | AI22: =IF(ISNA(O22),"",TEXT(O22,"+#,##0")) -> +0 | AJ22: =P22/$W$12 -> 0 | AK22: =IF(ISNA(P22),"",TEXT(P22,"""-""#,##0")) -> -0 | AL22: =Q22/$W$12 -> 0.086585795 | AM22: =IF(ISNA(Q22),"",TEXT(Q22,"+#,##0")) -> +985 | AN22: =R22/$W$12 -> 0 | AO22: =IF(ISNA(R22),"",TEXT(R22,"""-""#,##0")) -> -0 | AP22: =S22/$X$12 -> #N/A | AQ22: =IF(ISNA(S22),"",TEXT(S22,"+0.0;-0.0")) | AR22: =T22/$X$12 -> -1 | AS22: =IF(ISNA(T22),"",TEXT(T22,"+0.0;-0.0")) -> -3648.1 | AT22: =U22/$X$12 -> 0 | AU22: =V22/$X$12 -> 1
A23: Oct | B23: FC | C23: state | D23: 993 | E23: 264 | F23: =D23-E23 -> 729 | G23: =IF(F23=0,NA(),E23/F23*100) -> 36.213992 | H23: =NA() -> #N/A | I23: =F23 -> 729 | J23: =IF($B23="AC",D23,NA()) -> #N/A | K23: =IF($B23="FC",D23,NA()) -> 993 | L23: =M23+E23 -> 11298 | M23: =L22 -> 11034 | N23: =MIN(M23,L23) -> 11034 | O23: =IF(AND($B23="AC",E23>0),E23,0) -> 0 | P23: =IF(AND($B23="AC",E23<0),-E23,0) -> 0 | Q23: =IF(AND($B23="FC",E23>0),E23,0) -> 264 | R23: =IF(AND($B23="FC",E23<0),-E23,0) -> 0 | S23: =IF(G23>0,G23,NA()) -> 36.213992 | T23: =IF(G23<0,G23,NA()) -> #N/A | U23: =IF(G23>0,G23,0) -> 36.213992 | V23: =IF(G23<0,-G23,0) -> 0 | Y23: =H23/$W$12 -> #N/A | Z23: =IF(ISNA(H23),"",TEXT(H23,"#,##0")) | AA23: =I23/$W$12 -> 0.064082278 | AB23: =IF(ISNA(I23),"",TEXT(I23,"#,##0")) -> 729 | AC23: =J23/$W$12 -> #N/A | AD23: =IF(ISNA(J23),"",TEXT(J23,"#,##0")) | AE23: =K23/$W$12 -> 0.08728903 | AF23: =IF(ISNA(K23),"",TEXT(K23,"#,##0")) -> 993 | AG23: =N23/$W$12 -> 0.96993671 | AH23: =O23/$W$12 -> 0 | AI23: =IF(ISNA(O23),"",TEXT(O23,"+#,##0")) -> +0 | AJ23: =P23/$W$12 -> 0 | AK23: =IF(ISNA(P23),"",TEXT(P23,"""-""#,##0")) -> -0 | AL23: =Q23/$W$12 -> 0.023206751 | AM23: =IF(ISNA(Q23),"",TEXT(Q23,"+#,##0")) -> +264 | AN23: =R23/$W$12 -> 0 | AO23: =IF(ISNA(R23),"",TEXT(R23,"""-""#,##0")) -> -0 | AP23: =S23/$X$12 -> 0.0099266779 | AQ23: =IF(ISNA(S23),"",TEXT(S23,"+0.0;-0.0")) -> +36.2 | AR23: =T23/$X$12 -> #N/A | AS23: =IF(ISNA(T23),"",TEXT(T23,"+0.0;-0.0")) | AT23: =U23/$X$12 -> 0.0099266779 | AU23: =V23/$X$12 -> 0
A24: Nov | B24: FC | C24: state | D24: 967 | E24: 78 | F24: =D24-E24 -> 889 | G24: =IF(F24=0,NA(),E24/F24*100) -> 8.7739033 | H24: =NA() -> #N/A | I24: =F24 -> 889 | J24: =IF($B24="AC",D24,NA()) -> #N/A | K24: =IF($B24="FC",D24,NA()) -> 967 | L24: =M24+E24 -> 11376 | M24: =L23 -> 11298 | N24: =MIN(M24,L24) -> 11298 | O24: =IF(AND($B24="AC",E24>0),E24,0) -> 0 | P24: =IF(AND($B24="AC",E24<0),-E24,0) -> 0 | Q24: =IF(AND($B24="FC",E24>0),E24,0) -> 78 | R24: =IF(AND($B24="FC",E24<0),-E24,0) -> 0 | S24: =IF(G24>0,G24,NA()) -> 8.7739033 | T24: =IF(G24<0,G24,NA()) -> #N/A | U24: =IF(G24>0,G24,0) -> 8.7739033 | V24: =IF(G24<0,-G24,0) -> 0 | Y24: =H24/$W$12 -> #N/A | Z24: =IF(ISNA(H24),"",TEXT(H24,"#,##0")) | AA24: =I24/$W$12 -> 0.078146976 | AB24: =IF(ISNA(I24),"",TEXT(I24,"#,##0")) -> 889 | AC24: =J24/$W$12 -> #N/A | AD24: =IF(ISNA(J24),"",TEXT(J24,"#,##0")) | AE24: =K24/$W$12 -> 0.085003516 | AF24: =IF(ISNA(K24),"",TEXT(K24,"#,##0")) -> 967 | AG24: =N24/$W$12 -> 0.99314346 | AH24: =O24/$W$12 -> 0 | AI24: =IF(ISNA(O24),"",TEXT(O24,"+#,##0")) -> +0 | AJ24: =P24/$W$12 -> 0 | AK24: =IF(ISNA(P24),"",TEXT(P24,"""-""#,##0")) -> -0 | AL24: =Q24/$W$12 -> 0.0068565401 | AM24: =IF(ISNA(Q24),"",TEXT(Q24,"+#,##0")) -> +78 | AN24: =R24/$W$12 -> 0 | AO24: =IF(ISNA(R24),"",TEXT(R24,"""-""#,##0")) -> -0 | AP24: =S24/$X$12 -> 0.0024050293 | AQ24: =IF(ISNA(S24),"",TEXT(S24,"+0.0;-0.0")) -> +8.8 | AR24: =T24/$X$12 -> #N/A | AS24: =IF(ISNA(T24),"",TEXT(T24,"+0.0;-0.0")) | AT24: =U24/$X$12 -> 0.0024050293 | AU24: =V24/$X$12 -> 0
